{"trial_id": "0000", "hyperparameters": {"space": [{"class_name": "Int", "config": {"name": "units", "default": null, "conditions": [], "min_value": 256, "max_value": 512, "step": 64, "sampling": "linear"}}, {"class_name": "Float", "config": {"name": "dropout", "default": 0.2, "conditions": [], "min_value": 0.2, "max_value": 0.5, "step": 0.1, "sampling": "linear"}}, {"class_name": "Choice", "config": {"name": "learning_rate", "default": 0.01, "conditions": [], "values": [0.01, 0.001, 0.0001], "ordered": true}}], "values": {"units": 320, "dropout": 0.30000000000000004, "learning_rate": 0.0001, "tuner/epochs": 2, "tuner/initial_epoch": 0, "tuner/bracket": 2, "tuner/round": 0}}, "metrics": {"metrics": {}}, "score": null, "best_step": 0, "status": "FAILED", "message": "Traceback (most recent call last):\n  File \"/home/pnamy/anaconda3/envs/py312/lib/python3.12/site-packages/keras_tuner/src/engine/base_tuner.py\", line 274, in _try_run_and_update_trial\n    self._run_and_update_trial(trial, *fit_args, **fit_kwargs)\n  File \"/home/pnamy/anaconda3/envs/py312/lib/python3.12/site-packages/keras_tuner/src/engine/base_tuner.py\", line 239, in _run_and_update_trial\n    results = self.run_trial(trial, *fit_args, **fit_kwargs)\n              ^^^^^^^^^^^^^^^^^^^^^^^^^^^^^^^^^^^^^^^^^^^^^^\n  File \"/home/pnamy/anaconda3/envs/py312/lib/python3.12/site-packages/keras_tuner/src/tuners/hyperband.py\", line 427, in run_trial\n    return super().run_trial(trial, *fit_args, **fit_kwargs)\n           ^^^^^^^^^^^^^^^^^^^^^^^^^^^^^^^^^^^^^^^^^^^^^^^^^\n  File \"/home/pnamy/anaconda3/envs/py312/lib/python3.12/site-packages/keras_tuner/src/engine/tuner.py\", line 314, in run_trial\n    obj_value = self._build_and_fit_model(trial, *args, **copied_kwargs)\n                ^^^^^^^^^^^^^^^^^^^^^^^^^^^^^^^^^^^^^^^^^^^^^^^^^^^^^^^^\n  File \"/home/pnamy/anaconda3/envs/py312/lib/python3.12/site-packages/keras_tuner/src/engine/tuner.py\", line 233, in _build_and_fit_model\n    results = self.hypermodel.fit(hp, model, *args, **kwargs)\n              ^^^^^^^^^^^^^^^^^^^^^^^^^^^^^^^^^^^^^^^^^^^^^^^\n  File \"/home/pnamy/anaconda3/envs/py312/lib/python3.12/site-packages/keras_tuner/src/engine/hypermodel.py\", line 149, in fit\n    return model.fit(*args, **kwargs)\n           ^^^^^^^^^^^^^^^^^^^^^^^^^^\n  File \"/home/pnamy/anaconda3/envs/py312/lib/python3.12/site-packages/keras/src/utils/traceback_utils.py\", line 122, in error_handler\n    raise e.with_traceback(filtered_tb) from None\n  File \"/home/pnamy/anaconda3/envs/py312/lib/python3.12/site-packages/keras/src/trainers/data_adapters/__init__.py\", line 113, in get_data_adapter\n    raise ValueError(f\"Unrecognized data type: x={x} (of type {type(x)})\")\nValueError: Unrecognized data type: x=[<keras.src.legacy.preprocessing.image.DirectoryIterator object at 0x7f832b21abd0>, array([[0.01129327, 0.4343728 , 1.        , ..., 0.01129327, 1.        ,\n        0.        ],\n       [0.00574675, 0.48877763, 1.        , ..., 0.00574675, 0.        ,\n        1.        ],\n       [0.02061321, 0.54576367, 1.        , ..., 0.02061321, 1.        ,\n        0.        ],\n       ...,\n       [0.        , 0.        , 0.        , ..., 0.        , 0.        ,\n        0.        ],\n       [0.17312568, 0.42851475, 1.        , ..., 0.17312568, 0.        ,\n        1.        ],\n       [0.05606132, 0.41124515, 1.        , ..., 0.05606132, 1.        ,\n        0.        ]])] (of type <class 'list'>)\n"}